Workbook

Sheet GUIDE_UTILISATION
B2: MODÈLE MH3SFCA-λ — Région Béni Mellal-Khénifra
B3: Projet de Fin d'Études (PFE) | Modified Huff 3-Step Floating Catchment Area avec coefficient de préférence sectorielle λ
B5: ARCHITECTURE DU FICHIER — 8 FEUILLES INTERCONNECTÉES
B6: Feuille | C6: Rôle | D6: Formule mathématique | E6: Inputs / Outputs
B7: Param | C7: Paramètres globaux du modèle | D7: β = −dmax² / ln(seuil) | E7: INPUT: dmax, α, seuil OUTPUT: β (calculé)
B8: Demande | C8: Population Pi de chaque commune i | D8: — (données brutes RGPH) | E8: INPUT: code géo., nom commune, population
B9: Offre | C9: Capacité Sj et préférence λj des 35 établissements | D9: Col F : λj × Sj (capacité effective) | E9: INPUT: Sj (lits), λj OUTPUT: λj×Sj auto-calculé
B10: Matrice_OD | C10: Temps de trajet dij (minutes) — matrice 135×35 | D10: — (données QGIS Origine-Destination) | E10: INPUT: dij bruts
B11: 1_Friction | C11: Décroissance gaussienne f(dij;β) | D11: f(dij;β) = exp(−dij²/β) si dij ≤ dmax | E11: OUTPUT: f ∈ [0,1] pour chaque paire (i,j)
B12: 2_Utilité | C12: Utilité brute Uij — Étape 1a | D12: Uij = λj · Sj^α · f(dij;β) | E12: OUTPUT: Uij & Σj Uij par commune
B13: 3_Huff | C13: Poids Huffij & Ratio Rj — Étapes 1b & 2 | D13: Huffij = Uij/ΣUik | Rj = (λj·Sj)/Σ(Huffij·Pi) | E13: OUTPUT: Huffij ∈[0,1], ΣHuff=1, Rj
B14: 4_SPAI | C14: Indice d'accessibilité final — Étape 3 | D14: SPAIi = Σj Huffij · Rj · f(dij;β) | E14: OUTPUT: SPAI, SPAI×1000, Rang
B17: COMMENT UTILISER CE MODÈLE — MODIFICATIONS DYNAMIQUES
B18: 🏥 Ajouter des lits à une clinique | C18: Feuille Offre → modifier Col C (Sj) pour la clinique concernée. → Rj, SPAI et Rang se recalculent automatiquement en cascade.
B19: 🔧 Changer le seuil de distance dmax | C19: Feuille Param → modifier B2 (dmax). → β se recalcule (B5), puis friction, utilité, Huff, Rj et SPAI suivent.
B20: ⚙ Modifier le coefficient λ | C20: Feuille Offre → modifier Col E (λj) pour un établissement. → Uij, Huffij, Rj et SPAI se recalculent. Effectuer une analyse de sensibilité λ ∈ [0,5 ; 0,95].
B21: 🏗 Simuler une nouvelle clinique privée | C21: Matrice_OD → ajouter une colonne avec les dij de la nouvelle clinique. → Offre → ajouter une ligne (Sj, λ=0,9). → Étendre les formules dans 1_Friction, 2_Utilité, 3_Huff, 4_SPAI.
B22: 📊 Lire les résultats | C22: Feuille 4_SPAI → col AM (SPAI), col AN (SPAI×1000), col AO (Rang). Pour la cartographie : exporter la col SPAI×1000 vers QGIS (jointure par Code géo.).
B24: CHAÎNE DE CALCUL COMPLÈTE — MH3SFCA-λ
B25: ① PARAM : β = −dmax² / ln(seuil) [Jörg et al., 2019, p. 29]
B26: ② FRICTION : f(dij;β) = exp(−dij²/β) si dij ≤ dmax, sinon 0 [Subal et al., 2021, p. 6]
B27: ③ UTILITÉ : Uij = λj × Sj^α × f(dij;β) [Extension MH3SFCA-λ — PFE Chapitre 3]
B28: ④ HUFF : Huffij = Uij / Σk Uik (∑j Huffij = 1) [Huff, 1964, p. 35 ; Jörg et al., 2019, p. 32]
B29: ⑤ Rj : Rj = (λj × Sj) / Σi (Huffij × Pi) [Correction λ — PFE Chapitre 3]
B30: ⑥ SPAI : SPAIi = Σj [Huffij × Rj × f(dij;β)] [Subal et al., 2021, p. 7]
B32: Références bibliographiques mobilisées dans ce modèle :
B33: • Huff, D.L. (1964). Defining and Estimating a Trading Area. Journal of Marketing, 28(3), 34–38.
B34: • Jörg, R., Widmer, M., & Weaver, B. (2019). Mesure de l'accessibilité aux soins de santé. Rapport OBSAN. Neuchâtel.
B35: • Luo, W., & Wang, F. (2003). Measures of Spatial Accessibility to Health Care in a GIS Environment. Environment and Planning B, 30(6), 865–884.
B36: • Subal, J., Jörg, R., & Widmer, M. (2021). Spatial Accessibility to Health Services. Swiss Health Observatory (Obsan), Working Paper.
B37: • Wan, N., Zou, B., & Sternberg, T. (2012). A 3-Step Floating Catchment Area Method for Analyzing Spatial Access to Health Services. International Journal of Geographical Information Science, 26(6), 1073–1089.

Sheet Param
A1: Paramètre | B1: Valeur | C1: Description
A2: dmax (min) | B2: 90 | C2: Seuil max temps de trajet
A3: α (alpha) | B3: 1 | C3: Élasticité attractivité
A4: Seuil f(dmax) | B4: 0.01 | C4: f(dmax) → ce seuil
A5: β (beta) | B5: =-(B2^2)/LN(B4) -> 1758.8927 | C5: Calculé: = -(dmax²)/LN(seuil)
A8: FEUILLE PARAM — Paramètres du modèle MH3SFCA-λ
A9: β = − d²max / ln(seuil) → cellule B5 = -(B2^2)/LN(B4)
A10: • dmax (B2) : seuil maximal de temps de trajet en minutes. Toute paire (i,j) avec d_ij > dmax reçoit f(d)=0.
A11: • α (B3) : élasticité de l'attractivité. α=1 → les patients sont attirés proportionnellement à la capacité Sj.
A12: • Seuil f(dmax) (B4) : valeur de la fonction gaussienne à d=dmax. Jörg et al. (2019, p.29) utilisent 0,01.
A13: • β (B5) : paramètre de friction calculé automatiquement via la formule ci-dessus.
A14: Interprétation : plus β est grand, plus la décroissance est lente (patients moins sensibles à la distance).
A15: • λ privé / λ public : coefficients de préférence sectorielle (extension originale — cf. Chapitre 3).
A16: RÈGLE : λ privé + λ public = 1. Valeurs issues des données CESE (2024) sur les flux AMO.
A17: ⚠ Ces valeurs sont en bleu dans la feuille Offre (col E). Modifier là pour une analyse de sensibilité.
A18: Référence des formules | B18: Auteur(s) | C18: Page
A19: Fonction gaussienne f(dij;β) | B19: Subal et al. (2021) | C19: p. 6
A20: Paramètre β = -dmax²/ln(seuil) | B20: Jörg et al. (2019) | C20: p. 29
A21: Coefficient α (élasticité) | B21: Huff (1964) | C21: p. 35
A22: Coefficient λ (préférence sectorielle) | B22: Extension originale — Chapitre 3 | C22: —

Sheet Demande
A1: Code géo. | B1: Commune | C1: Population
A2: 05.091.01.01. | B2: Commune de Béni Mellal | C2: 209594
A3: 05.091.01.07. | B3: Commune de Kasba Tadla | C3: 48172
A4: 05.091.01.13. | B4: Commune de Zaouiat Cheikh | C4: 25088
A5: 05.091.01.03. | B5: Commune d'El Ksiba | C5: 19964
A6: 05.091.03.03. | B6: Commune d'Ouled Gnaou | C6: 13366
A7: 05.091.03.05. | B7: Commune d'Ouled M'barek | C7: 21636
A8: 05.091.03.01. | B8: Commune de Foum Oudi | C8: 16256
A9: 05.091.03.07. | B9: Commune d'Ouled Yaich | C9: 25785
A10: 05.091.03.09. | B10: Commune de Sidi Jaber | C10: 20455
A11: 05.091.03.11. | B11: Commune de Foum El Anceur | C11: 24232
A12: 05.091.07.11. | B12: Commune de Naour | C12: 5389
A13: 05.091.07.07. | B13: Commune de Dir El Ksiba | C13: 25851
... A136: 05.311.07.13. | B136: Commune d'Oulad Aissa | C136: 4652

Sheet Offre
A1: j | B1: Nom_etablissement | C1: Sj (lits) | D1: type_etab | E1: Lambda | F1: λ×Sj
A2: 1 | B2: DAR ESSALAM - Fkih Ben Saleh | C2: 16 | D2: clinique privée | E2: 0.9 | F2: =E2*C2 -> 14.4
A3: 2 | B3: NOUR - Beni Mellal | C3: 10 | D3: clinique privée | E3: 0.9 | F3: =E3*C3 -> 9
A4: 3 | B4: HÃ´pital PrivÃ© Al-Farabi - Beni Mellal | C4: 111 | D4: clinique privée | E4: 0.9 | F4: =E4*C4 -> 99.9
A5: 4 | B5: BEN ASSOU - Beni Mellal | C5: 20 | D5: clinique privée | E5: 0.9 | F5: =E5*C5 -> 18
A6: 5 | B6: JABRANE - Beni Mellal | C6: 57 | D6: clinique privée | E6: 0.9 | F6: =E6*C6 -> 51.3
A7: 6 | B7: BOUHOU - Beni Mellal | C7: 13 | D7: clinique privée | E7: 0.9 | F7: =E7*C7 -> 11.7
A8: 7 | B8: BENI MELLAL - Beni Mellal | C8: 30 | D8: clinique privée | E8: 0.9 | F8: =E8*C8 -> 27
A9: 8 | B9: MALAK - Beni Mellal | C9: 24 | D9: clinique privée | E9: 0.9 | F9: =E9*C9 -> 21.6
A10: 9 | B10: ERRAZI - Beni Mellal | C10: 15 | D10: clinique privée | E10: 0.9 | F10: =E10*C10 -> 13.5
A11: 10 | B11: AL CHIFA - Beni Mellal | C11: 15 | D11: clinique privée | E11: 0.9 | F11: =E11*C11 -> 13.5
A12: 11 | B12: Clinique International Beni Mellal - Beni Mellal | C12: 80 | D12: clinique privée | E12: 0.9 | F12: =E12*C12 -> 72
A13: 12 | B13: AL ADDARISSA - Beni Mellal | C13: 11 | D13: clinique privée | E13: 0.9 | F13: =E13*C13 -> 9.9
... A39: 38 | B39: CLINIQUE PRIVÉE - Demnate (Simulation) | C39: 40 | D39: clinique privée | E39: 0.9 | F39: =E39*C39 -> 36
A40: • Col C (Sj — BLEU) : nombre de lits agréés. MODIFIABLE → toutes les feuilles suivantes se recalculent.
A41: FEUILLE OFFRE — Données de l'offre de soins (35 établissements)
A42: Colonne F : λj × Sj → formule : =E{j}*C{j} (capacité effective perçue)
A43: • Col C (Sj — BLEU) : nombre de lits agréés. MODIFIABLE → toutes les feuilles suivantes se recalculent.
A44: • Col E (λj — BLEU) : coefficient de préférence sectorielle. λ=0,9 pour cliniques privées ; λ=0,1 pour hôpitaux publics.
A45: • Col F = λj × Sj : capacité effective utilisée au NUMÉRATEUR de Rj (étape 2). C'est la CORRECTION de l'erreur initiale.
A46: Justification : Rj = (λj×Sj) / Σ(Huffij×Pi) assure la cohérence — l'offre et la demande sont toutes deux pondérées par λ.
A47: Référence : Extension MH3SFCA-λ développée dans ce PFE ; cf. Chapitre 3, section 3.x.
A48: • ⚠ L'ordre des lignes ici correspond EXACTEMENT à l'ordre des colonnes de la Matrice_OD.
A49: Ne pas réordonner les lignes de cette feuille sans reporter le même changement dans Matrice_OD.

Sheet Matrice_OD
A1: Code géo. | B1: Commune | C1: DAR ESSALAM - Fkih Ben Saleh | D1: NOUR - Beni Mellal | E1: HÃ´pital PrivÃ© Al-Farabi - Beni Mellal | F1: BEN ASSOU - Beni Mellal | G1: JABRANE - Beni Mellal | H1: BOUHOU - Beni Mellal | I1: BENI MELLAL - Beni Mellal | J1: MALAK - Beni Mellal | K1: ERRAZI - Beni Mellal | L1: AL CHIFA - Beni Mellal | M1: Clinique International Beni Mellal - Beni Mellal | N1: AL ADDARISSA - Beni Mellal | O1: ATLAS - Beni Mellal | P1: ASSALAM - Beni Mellal | Q1: HÃ´pital PrivÃ© de Beni Mellal (Akdital) - Beni Mellal | R1: AMAL - Beni Mellal | S1: IBN SINA - Beni Mellal | T1: LES OLIVIERS YASMINE - Fkih Ben Saleh | U1: Le Lac - Khouribga | V1: Clinique multidisciplinaire-OCP - Khouribga | W1: MARJANE - Khouribga | X1: CHIFA - Khouribga | Y1: DAKHLA - Khouribga | Z1: MOULAY YOUSSEF - Khouribga | AA1: Akdital - Khouribga | AB1: Al Ikhwa - Khouribga | AC1: M. D'ACCOUCHEMENT - Khenifra | AD1: EL AMAL - Khenifra | AE1: ACHIFFA (KARRAOUA) - Khenifra | AF1: LE CEDRE - Khenifra | AG1: Hôpital Provincial d'Azilal | AH1: Hôpital Régional de Béni Mellal | AI1: Hôpital Provincial de Fkih Ben Saleh | AJ1: Hôpital Hassan II (CHP) | AK1: Hôpital Provincial de Khénifra | AL1: CLINIQUE PRIVÉE - Khénifra (Simulation) | AM1: CLINIQUE PRIVÉE - Souk Sebt (Simulation) | AN1: CLINIQUE PRIVÉE - Demnate (Simulation)
A2: 05.091.01.01. | B2: Commune de Béni Mellal | C2: 35.97 | D2: 5.1 | E2: 4.81 | F2: 3.64 | G2: 3.15 | H2: 3.6 | I2: 2.4 | J2: 3.11 | K2: 1.59 | L2: 1.76 | M2: 4.04 | N2: 4.02 | O2: 1.79 | P2: 2.3 | Q2: 2.09 | R2: 2.59 | S2: 2.51 | T2: 40.31 | U2: 51.97 | V2: 74.38 | W2: 76.07 | X2: 74.71 | Y2: 74.73 | Z2: 75.02 | AA2: 74.5 | AB2: 73.27 | AC2: 122.1 | AD2: 122.53 | AE2: 123.35 | AF2: 123.45 | AG2: 90.51 | AH2: 3.28 | AI2: 41.23 | AJ2: 75.56 | AK2: 127.92 | AL2: 123.4 | AM2: 37.6 | AN2: 138.1
A3: 05.091.01.07. | B3: Commune de Kasba Tadla | C3: 70.38 | D3: 40.1 | E3: 39.81 | F3: 39.54 | G3: 39.82 | H3: 37.56 | I3: 37.76 | J3: 38.47 | K3: 39.19 | L3: 37.74 | M3: 36.53 | N3: 38.3 | O3: 38.13 | P3: 37.76 | Q3: 37.66 | R3: 37.86 | S3: 38.45 | T3: 43.72 | U3: 43.98 | V3: 69.82 | W3: 68.08 | X3: 66.72 | Y3: 66.73 | Z3: 67.02 | AA3: 66.51 | AB3: 65.28 | AC3: 94.33 | AD3: 94.77 | AE3: 95.59 | AF3: 95.68 | AG3: 125.5 | AH3: 36.91 | AI3: 44.64 | AJ3: 67.56 | AK3: 100.15 | AL3: 95.6 | AM3: 71.3 | AN3: 173.1
A4: 05.091.01.13. | B4: Commune de Zaouiat Cheikh | C4: 94.92 | D4: 64.05 | E4: 63.77 | F4: 63.49 | G4: 63.78 | H4: 61.52 | I4: 61.72 | J4: 62.43 | K4: 63.15 | L4: 61.7 | M4: 60.49 | N4: 62.25 | O4: 62.09 | P4: 61.72 | Q4: 61.62 | R4: 61.81 | S4: 62.4 | T4: 71.86 | U4: 72.12 | V4: 97.96 | W4: 96.23 | X4: 94.86 | Y4: 94.88 | Z4: 95.17 | AA4: 94.65 | AB4: 93.43 | AC4: 58.94 | AD4: 59.37 | AE4: 60.19 | AF4: 60.28 | AG4: 149.46 | AH4: 60.87 | AI4: 72.79 | AJ4: 95.71 | AK4: 64.75 | AL4: 60.2 | AM4: 96.6 | AN4: 197.1
A5: 05.091.01.03. | B5: Commune d'El Ksiba | C5: 89.69 | D5: 58.82 | E5: 58.53 | F5: 58.26 | G5: 58.54 | H5: 56.28 | I5: 56.49 | J5: 57.19 | K5: 57.91 | L5: 56.46 | M5: 55.25 | N5: 57.02 | O5: 56.85 | P5: 56.48 | Q5: 56.38 | R5: 56.58 | S5: 57.17 | T5: 67.64 | U5: 67.9 | V5: 93.74 | W5: 92 | X5: 90.64 | Y5: 90.65 | Z5: 90.94 | AA5: 90.43 | AB5: 89.2 | AC5: 79.45 | AD5: 79.88 | AE5: 80.7 | AF5: 80.79 | AG5: 144.22 | AH5: 55.64 | AI5: 68.56 | AJ5: 91.48 | AK5: 85.26 | AL5: 80.7 | AM5: 91.3 | AN5: 191.8
A6: 05.091.03.03. | B6: Commune d'Ouled Gnaou | C6: 27.67 | D6: 21.84 | E6: 23.24 | F6: 22.97 | G6: 23.88 | H6: 20.99 | I6: 22.86 | J6: 23.39 | K6: 23.58 | L6: 22.83 | M6: 21.74 | N6: 22.94 | O6: 23.22 | P6: 23.31 | Q6: 23.65 | R6: 23.78 | S6: 24.06 | T6: 41.27 | U6: 69.26 | V6: 75.34 | W6: 77.5 | X6: 77.61 | Y6: 77.63 | Z6: 77.92 | AA6: 79.37 | AB6: 80.1 | AC6: 139.39 | AD6: 139.83 | AE6: 140.64 | AF6: 140.74 | AG6: 89.36 | AH6: 24.84 | AI6: 40.88 | AJ6: 78.46 | AK6: 145.21 | AL6: 140.7 | AM6: 28.6 | AN6: 134
A7: 05.091.03.05. | B7: Commune d'Ouled M'barek | C7: 22.8 | D7: 14.52 | E7: 16.08 | F7: 16.19 | G7: 16.72 | H7: 17.37 | I7: 17.5 | J7: 17.81 | K7: 18 | L7: 18.08 | M7: 18.11 | N7: 18.4 | O7: 18.46 | P7: 18.56 | Q7: 18.89 | R7: 19.02 | S7: 19.3 | T7: 44.14 | U7: 66.78 | V7: 78.22 | W7: 80.38 | X7: 80.49 | Y7: 80.51 | Z7: 80.8 | AA7: 82.25 | AB7: 82.97 | AC7: 136.91 | AD7: 137.34 | AE7: 138.16 | AF7: 138.26 | AG7: 77.34 | AH7: 20.08 | AI7: 45.07 | AJ7: 81.34 | AK7: 142.72 | AL7: 138.2 | AM7: 24.4 | AN7: 124.9
A8: 05.091.03.01. | B8: Commune de Foum Oudi | C8: 32.58 | D8: 13.32 | E8: 14.88 | F8: 14.99 | G8: 15.52 | H8: 16.17 | I8: 16.3 | J8: 16.61 | K8: 16.8 | L8: 16.88 | M8: 16.91 | N8: 17.2 | O8: 17.27 | P8: 17.36 | Q8: 17.7 | R8: 17.82 | S8: 18.11 | T8: 45.8 | U8: 65.58 | V8: 79.88 | W8: 82.04 | X8: 82.15 | Y8: 82.16 | Z8: 82.45 | AA8: 83.91 | AB8: 84.63 | AC8: 135.71 | AD8: 136.15 | AE8: 136.96 | AF8: 137.06 | AG8: 86.35 | AH8: 18.88 | AI8: 46.73 | AJ8: 82.99 | AK8: 141.53 | AL8: 137 | AM8: 34.2 | AN8: 134.7
A9: 05.091.03.07. | B9: Commune d'Ouled Yaich | C9: 51.13 | D9: 20.26 | E9: 19.97 | F9: 19.7 | G9: 19.98 | H9: 17.72 | I9: 17.93 | J9: 18.63 | K9: 19.35 | L9: 17.9 | M9: 16.69 | N9: 18.46 | O9: 18.29 | P9: 17.92 | Q9: 17.82 | R9: 18.02 | S9: 18.61 | T9: 46.35 | U9: 44.33 | V9: 70.17 | W9: 68.43 | X9: 67.07 | Y9: 67.08 | Z9: 67.37 | AA9: 66.86 | AB9: 65.63 | AC9: 107.46 | AD9: 107.9 | AE9: 108.72 | AF9: 108.81 | AG9: 105.66 | AH9: 17.08 | AI9: 47.27 | AJ9: 67.91 | AK9: 113.28 | AL9: 108.8 | AM9: 52.8 | AN9: 153.3
A10: 05.091.03.09. | B10: Commune de Sidi Jaber | C10: 38.17 | D10: 12.27 | E10: 13.66 | F10: 13.39 | G10: 14.3 | H10: 11.42 | I10: 13.28 | J10: 13.81 | K10: 14 | L10: 13.26 | M10: 12.16 | N10: 13.36 | O10: 13.64 | P10: 13.74 | Q10: 14.07 | R10: 14.2 | S10: 14.48 | T10: 30.33 | U10: 59.69 | V10: 64.4 | W10: 66.56 | X10: 66.67 | Y10: 66.69 | Z10: 66.98 | AA10: 68.43 | AB10: 69.16 | AC10: 129.81 | AD10: 130.25 | AE10: 131.07 | AF10: 131.16 | AG10: 92.7 | AH10: 15.26 | AI10: 31.25 | AJ10: 67.52 | AK10: 135.63 | AL10: 131.1 | AM10: 39.8 | AN10: 140.3
A11: 05.091.03.11. | B11: Commune de Foum El Anceur | C11: 63 | D11: 27 | E11: 27 | F11: 26 | G11: 24 | H11: 26 | I11: 23 | J11: 24 | K11: 24 | L11: 22 | M11: 27 | N11: 24 | O11: 23 | P11: 22 | Q11: 21 | R11: 22 | S11: 22 | T11: 66 | U11: 81 | V11: 112 | W11: 115 | X11: 113 | Y11: 114 | Z11: 116 | AA11: 116 | AB11: 117 | AC11: 135 | AD11: 135 | AE11: 137 | AF11: 138 | AG11: 122 | AH11: 21 | AI11: 66 | AJ11: 115 | AK11: 150 | AL11: 140 | AM11: 62 | AN11: 165
A12: 05.091.07.11. | B12: Commune de Naour | C12: 137.12 | D12: 106.25 | E12: 105.96 | F12: 105.69 | G12: 105.97 | H12: 103.71 | I12: 103.91 | J12: 104.62 | K12: 105.34 | L12: 103.89 | M12: 102.68 | N12: 104.45 | O12: 104.28 | P12: 103.91 | Q12: 103.81 | R12: 104.01 | S12: 104.6 | T12: 114.06 | U12: 114.31 | V12: 140.15 | W12: 138.42 | X12: 137.05 | Y12: 137.07 | Z12: 137.36 | AA12: 136.84 | AB12: 135.62 | AC12: 124.55 | AD12: 124.99 | AE12: 125.8 | AF12: 125.9 | AG12: 159.02 | AH12: 103.06 | AI12: 114.98 | AJ12: 137.9 | AK12: 130.37 | AL12: 125.9 | AM12: 138.8 | AN12: 236.7
A13: 05.091.07.07. | B13: Commune de Dir El Ksiba | C13: 89.47 | D13: 58.6 | E13: 58.31 | F13: 58.04 | G13: 58.33 | H13: 56.07 | I13: 56.27 | J13: 56.98 | K13: 57.69 | L13: 56.25 | M13: 55.04 | N13: 56.8 | O13: 56.64 | P13: 56.27 | Q13: 56.16 | R13: 56.36 | S13: 56.95 | T13: 69.08 | U13: 69.34 | V13: 95.18 | W13: 93.44 | X13: 92.08 | Y13: 92.1 | Z13: 92.39 | AA13: 91.87 | AB13: 90.65 | AC13: 80.89 | AD13: 81.33 | AE13: 82.14 | AF13: 82.24 | AG13: 144.01 | AH13: 55.42 | AI13: 70.01 | AJ13: 92.93 | AK13: 86.71 | AL13: 82.2 | AM13: 91.1 | AN13: 191.6
... A136: 05.311.07.13. | B136: Commune d'Oulad Aissa | C136: 119.36 | D136: 99.41 | E136: 99.12 | F136: 98.85 | G136: 99.13 | H136: 96.87 | I136: 97.08 | J136: 97.78 | K136: 98.5 | L136: 97.05 | M136: 95.84 | N136: 97.61 | O136: 97.44 | P136: 97.07 | Q136: 96.97 | R136: 97.17 | S136: 97.76 | T136: 91.13 | U136: 50.84 | V136: 82.18 | W136: 80.9 | X136: 79.54 | Y136: 79.56 | Z136: 79.85 | AA136: 79.33 | AB136: 78.1 | AC136: 136.09 | AD136: 135.71 | AE136: 135.73 | AF136: 136.42 | AG136: 184.81 | AH136: 96.23 | AI136: 93.01 | AJ136: 80.39 | AK136: 140.13 | AL136: 136.2 | AM136: 120.3 | AN136: 225.6
A137: FEUILLE MATRICE_OD — Temps de trajet dij (minutes) entre 135 communes et 35 établissements
A138: Source : Matrice Origine-Destination calculée sous QGIS via l'algorithme OD Matrix (réseau routier réel)
A139: • dij = temps de trajet (minutes) entre la commune i et l'établissement j. Valeurs issues de QGIS.
A140: • Ces données sont des INPUTS bruts — aucune formule, seulement des valeurs mesurées.
A141: • Elles sont référencées dans 1_Friction par : Matrice_OD!{col}{ligne} ≤ Param!$B$2 (test dmax).
A142: • Si vous mettez à jour les temps de trajet (nouveau réseau, nouvelle clinique), copiez ici → tout se recalcule.
A143: • Colonnes : 35 établissements dans le MÊME ordre que la feuille Offre. Lignes : 135 communes.

Sheet 1_Friction
A1: Code géo. | B1: Commune | C1: DAR ESSALAM - Fkih Ben Saleh | D1: NOUR - Beni Mellal | E1: HÃ´pital PrivÃ© Al-Farabi - Beni Mellal | F1: BEN ASSOU - Beni Mellal | G1: JABRANE - Beni Mellal | H1: BOUHOU - Beni Mellal | I1: BENI MELLAL - Beni Mellal | J1: MALAK - Beni Mellal | K1: ERRAZI - Beni Mellal | L1: AL CHIFA - Beni Mellal | M1: Clinique International Beni Mellal - Beni Mellal | N1: AL ADDARISSA - Beni Mellal | O1: ATLAS - Beni Mellal | P1: ASSALAM - Beni Mellal | Q1: HÃ´pital PrivÃ© de Beni Mellal (Akdital) - Beni Mellal | R1: AMAL - Beni Mellal | S1: IBN SINA - Beni Mellal | T1: LES OLIVIERS YASMINE - Fkih Ben Saleh | U1: Le Lac - Khouribga | V1: Clinique multidisciplinaire-OCP - Khouribga | W1: MARJANE - Khouribga | X1: CHIFA - Khouribga | Y1: DAKHLA - Khouribga | Z1: MOULAY YOUSSEF - Khouribga | AA1: Akdital - Khouribga | AB1: Al Ikhwa - Khouribga | AC1: M. D'ACCOUCHEMENT - Khenifra | AD1: EL AMAL - Khenifra | AE1: ACHIFFA (KARRAOUA) - Khenifra | AF1: LE CEDRE - Khenifra | AG1: Hôpital Provincial d'Azilal | AH1: Hôpital Régional de Béni Mellal | AI1: Hôpital Provincial de Fkih Ben Saleh | AJ1: Hôpital Hassan II (CHP) | AK1: Hôpital Provincial de Khénifra | AL1: CLINIQUE PRIVÉE - Khénifra (Simulation) | AM1: CLINIQUE PRIVÉE - Souk Sebt (Simulation) | AN1: CLINIQUE PRIVÉE - Demnate (Simulation)
A2: 05.091.01.01. | B2: Commune de Béni Mellal | C2: =IF(Matrice_OD!C2<=Param!$B$2,EXP(-(Matrice_OD!C2^2)/Param!$B$5),0) -> 0.47921799 | D2: =IF(Matrice_OD!D2<=Param!$B$2,EXP(-(Matrice_OD!D2^2)/Param!$B$5),0) -> 0.98532109 | E2: =IF(Matrice_OD!E2<=Param!$B$2,EXP(-(Matrice_OD!E2^2)/Param!$B$5),0) -> 0.98693235 | F2: =IF(Matrice_OD!F2<=Param!$B$2,EXP(-(Matrice_OD!F2^2)/Param!$B$5),0) -> 0.99249538 | G2: =IF(Matrice_OD!G2<=Param!$B$2,EXP(-(Matrice_OD!G2^2)/Param!$B$5),0) -> 0.99437455 | H2: =IF(Matrice_OD!H2<=Param!$B$2,EXP(-(Matrice_OD!H2^2)/Param!$B$5),0) -> 0.99265881 | I2: =IF(Matrice_OD!I2<=Param!$B$2,EXP(-(Matrice_OD!I2^2)/Param!$B$5),0) -> 0.99673057 | J2: =IF(Matrice_OD!J2<=Param!$B$2,EXP(-(Matrice_OD!J2^2)/Param!$B$5),0) -> 0.99451612 | ... AN2: =IF(Matrice_OD!AN2<=Param!$B$2,EXP(-(Matrice_OD!AN2^2)/Param!$B$5),0) -> 0
A3: 05.091.01.07. | B3: Commune de Kasba Tadla | C3: =IF(Matrice_OD!C3<=Param!$B$2,EXP(-(Matrice_OD!C3^2)/Param!$B$5),0) -> 0.059834546 | D3: =IF(Matrice_OD!D3<=Param!$B$2,EXP(-(Matrice_OD!D3^2)/Param!$B$5),0) -> 0.40083025 | E3: =IF(Matrice_OD!E3<=Param!$B$2,EXP(-(Matrice_OD!E3^2)/Param!$B$5),0) -> 0.40614625 | F3: =IF(Matrice_OD!F3<=Param!$B$2,EXP(-(Matrice_OD!F3^2)/Param!$B$5),0) -> 0.41112363 | G3: =IF(Matrice_OD!G3<=Param!$B$2,EXP(-(Matrice_OD!G3^2)/Param!$B$5),0) -> 0.40596241 | H3: =IF(Matrice_OD!H3<=Param!$B$2,EXP(-(Matrice_OD!H3^2)/Param!$B$5),0) -> 0.44840018 | I3: =IF(Matrice_OD!I3<=Param!$B$2,EXP(-(Matrice_OD!I3^2)/Param!$B$5),0) -> 0.44457626 | J3: =IF(Matrice_OD!J3<=Param!$B$2,EXP(-(Matrice_OD!J3^2)/Param!$B$5),0) -> 0.43110444 | ... AN3: =IF(Matrice_OD!AN3<=Param!$B$2,EXP(-(Matrice_OD!AN3^2)/Param!$B$5),0) -> 0
A4: 05.091.01.13. | B4: Commune de Zaouiat Cheikh | C4: =IF(Matrice_OD!C4<=Param!$B$2,EXP(-(Matrice_OD!C4^2)/Param!$B$5),0) -> 0 | D4: =IF(Matrice_OD!D4<=Param!$B$2,EXP(-(Matrice_OD!D4^2)/Param!$B$5),0) -> 0.097064654 | E4: =IF(Matrice_OD!E4<=Param!$B$2,EXP(-(Matrice_OD!E4^2)/Param!$B$5),0) -> 0.099059937 | F4: =IF(Matrice_OD!F4<=Param!$B$2,EXP(-(Matrice_OD!F4^2)/Param!$B$5),0) -> 0.10108722 | G4: =IF(Matrice_OD!G4<=Param!$B$2,EXP(-(Matrice_OD!G4^2)/Param!$B$5),0) -> 0.098988128 | H4: =IF(Matrice_OD!H4<=Param!$B$2,EXP(-(Matrice_OD!H4^2)/Param!$B$5),0) -> 0.11627962 | I4: =IF(Matrice_OD!I4<=Param!$B$2,EXP(-(Matrice_OD!I4^2)/Param!$B$5),0) -> 0.11466152 | J4: =IF(Matrice_OD!J4<=Param!$B$2,EXP(-(Matrice_OD!J4^2)/Param!$B$5),0) -> 0.10905689 | ... AN4: =IF(Matrice_OD!AN4<=Param!$B$2,EXP(-(Matrice_OD!AN4^2)/Param!$B$5),0) -> 0
A5: 05.091.01.03. | B5: Commune d'El Ksiba | C5: =IF(Matrice_OD!C5<=Param!$B$2,EXP(-(Matrice_OD!C5^2)/Param!$B$5),0) -> 0.010321767 | D5: =IF(Matrice_OD!D5<=Param!$B$2,EXP(-(Matrice_OD!D5^2)/Param!$B$5),0) -> 0.13987183 | E5: =IF(Matrice_OD!E5<=Param!$B$2,EXP(-(Matrice_OD!E5^2)/Param!$B$5),0) -> 0.14260446 | F5: =IF(Matrice_OD!F5<=Param!$B$2,EXP(-(Matrice_OD!F5^2)/Param!$B$5),0) -> 0.14518412 | G5: =IF(Matrice_OD!G5<=Param!$B$2,EXP(-(Matrice_OD!G5^2)/Param!$B$5),0) -> 0.14250958 | H5: =IF(Matrice_OD!H5<=Param!$B$2,EXP(-(Matrice_OD!H5^2)/Param!$B$5),0) -> 0.1651644 | I5: =IF(Matrice_OD!I5<=Param!$B$2,EXP(-(Matrice_OD!I5^2)/Param!$B$5),0) -> 0.16295553 | J5: =IF(Matrice_OD!J5<=Param!$B$2,EXP(-(Matrice_OD!J5^2)/Param!$B$5),0) -> 0.15574737 | ... AN5: =IF(Matrice_OD!AN5<=Param!$B$2,EXP(-(Matrice_OD!AN5^2)/Param!$B$5),0) -> 0
A6: 05.091.03.03. | B6: Commune d'Ouled Gnaou | C6: =IF(Matrice_OD!C6<=Param!$B$2,EXP(-(Matrice_OD!C6^2)/Param!$B$5),0) -> 0.6470768 | D6: =IF(Matrice_OD!D6<=Param!$B$2,EXP(-(Matrice_OD!D6^2)/Param!$B$5),0) -> 0.7624753 | E6: =IF(Matrice_OD!E6<=Param!$B$2,EXP(-(Matrice_OD!E6^2)/Param!$B$5),0) -> 0.73560144 | F6: =IF(Matrice_OD!F6<=Param!$B$2,EXP(-(Matrice_OD!F6^2)/Param!$B$5),0) -> 0.74083797 | G6: =IF(Matrice_OD!G6<=Param!$B$2,EXP(-(Matrice_OD!G6^2)/Param!$B$5),0) -> 0.72309681 | H6: =IF(Matrice_OD!H6<=Param!$B$2,EXP(-(Matrice_OD!H6^2)/Param!$B$5),0) -> 0.77842144 | I6: =IF(Matrice_OD!I6<=Param!$B$2,EXP(-(Matrice_OD!I6^2)/Param!$B$5),0) -> 0.74296439 | J6: =IF(Matrice_OD!J6<=Param!$B$2,EXP(-(Matrice_OD!J6^2)/Param!$B$5),0) -> 0.73268201 | ... AN6: =IF(Matrice_OD!AN6<=Param!$B$2,EXP(-(Matrice_OD!AN6^2)/Param!$B$5),0) -> 0
A7: 05.091.03.05. | B7: Commune d'Ouled M'barek | C7: =IF(Matrice_OD!C7<=Param!$B$2,EXP(-(Matrice_OD!C7^2)/Param!$B$5),0) -> 0.74412251 | D7: =IF(Matrice_OD!D7<=Param!$B$2,EXP(-(Matrice_OD!D7^2)/Param!$B$5),0) -> 0.88703981 | E7: =IF(Matrice_OD!E7<=Param!$B$2,EXP(-(Matrice_OD!E7^2)/Param!$B$5),0) -> 0.86328947 | F7: =IF(Matrice_OD!F7<=Param!$B$2,EXP(-(Matrice_OD!F7^2)/Param!$B$5),0) -> 0.86154899 | G7: =IF(Matrice_OD!G7<=Param!$B$2,EXP(-(Matrice_OD!G7^2)/Param!$B$5),0) -> 0.85304754 | H7: =IF(Matrice_OD!H7<=Param!$B$2,EXP(-(Matrice_OD!H7^2)/Param!$B$5),0) -> 0.84236827 | I7: =IF(Matrice_OD!I7<=Param!$B$2,EXP(-(Matrice_OD!I7^2)/Param!$B$5),0) -> 0.84020008 | J7: =IF(Matrice_OD!J7<=Param!$B$2,EXP(-(Matrice_OD!J7^2)/Param!$B$5),0) -> 0.8349875 | ... AN7: =IF(Matrice_OD!AN7<=Param!$B$2,EXP(-(Matrice_OD!AN7^2)/Param!$B$5),0) -> 0
A8: 05.091.03.01. | B8: Commune de Foum Oudi | C8: =IF(Matrice_OD!C8<=Param!$B$2,EXP(-(Matrice_OD!C8^2)/Param!$B$5),0) -> 0.54690513 | D8: =IF(Matrice_OD!D8<=Param!$B$2,EXP(-(Matrice_OD!D8^2)/Param!$B$5),0) -> 0.90404906 | E8: =IF(Matrice_OD!E8<=Param!$B$2,EXP(-(Matrice_OD!E8^2)/Param!$B$5),0) -> 0.88171814 | F8: =IF(Matrice_OD!F8<=Param!$B$2,EXP(-(Matrice_OD!F8^2)/Param!$B$5),0) -> 0.88007259 | G8: =IF(Matrice_OD!G8<=Param!$B$2,EXP(-(Matrice_OD!G8^2)/Param!$B$5),0) -> 0.87201876 | H8: =IF(Matrice_OD!H8<=Param!$B$2,EXP(-(Matrice_OD!H8^2)/Param!$B$5),0) -> 0.86186606 | I8: =IF(Matrice_OD!I8<=Param!$B$2,EXP(-(Matrice_OD!I8^2)/Param!$B$5),0) -> 0.85980018 | J8: =IF(Matrice_OD!J8<=Param!$B$2,EXP(-(Matrice_OD!J8^2)/Param!$B$5),0) -> 0.85482752 | ... AN8: =IF(Matrice_OD!AN8<=Param!$B$2,EXP(-(Matrice_OD!AN8^2)/Param!$B$5),0) -> 0
A9: 05.091.03.07. | B9: Commune d'Ouled Yaich | C9: =IF(Matrice_OD!C9<=Param!$B$2,EXP(-(Matrice_OD!C9^2)/Param!$B$5),0) -> 0.22620361 | D9: =IF(Matrice_OD!D9<=Param!$B$2,EXP(-(Matrice_OD!D9^2)/Param!$B$5),0) -> 0.79186286 | E9: =IF(Matrice_OD!E9<=Param!$B$2,EXP(-(Matrice_OD!E9^2)/Param!$B$5),0) -> 0.79713273 | F9: =IF(Matrice_OD!F9<=Param!$B$2,EXP(-(Matrice_OD!F9^2)/Param!$B$5),0) -> 0.80200174 | G9: =IF(Matrice_OD!G9<=Param!$B$2,EXP(-(Matrice_OD!G9^2)/Param!$B$5),0) -> 0.7969517 | H9: =IF(Matrice_OD!H9<=Param!$B$2,EXP(-(Matrice_OD!H9^2)/Param!$B$5),0) -> 0.83650691 | I9: =IF(Matrice_OD!I9<=Param!$B$2,EXP(-(Matrice_OD!I9^2)/Param!$B$5),0) -> 0.83295399 | J9: =IF(Matrice_OD!J9<=Param!$B$2,EXP(-(Matrice_OD!J9^2)/Param!$B$5),0) -> 0.8209222 | ... AN9: =IF(Matrice_OD!AN9<=Param!$B$2,EXP(-(Matrice_OD!AN9^2)/Param!$B$5),0) -> 0
A10: 05.091.03.09. | B10: Commune de Sidi Jaber | C10: =IF(Matrice_OD!C10<=Param!$B$2,EXP(-(Matrice_OD!C10^2)/Param!$B$5),0) -> 0.43677677 | D10: =IF(Matrice_OD!D10<=Param!$B$2,EXP(-(Matrice_OD!D10^2)/Param!$B$5),0) -> 0.91796568 | E10: =IF(Matrice_OD!E10<=Param!$B$2,EXP(-(Matrice_OD!E10^2)/Param!$B$5),0) -> 0.89934642 | F10: =IF(Matrice_OD!F10<=Param!$B$2,EXP(-(Matrice_OD!F10^2)/Param!$B$5),0) -> 0.90308857 | G10: =IF(Matrice_OD!G10<=Param!$B$2,EXP(-(Matrice_OD!G10^2)/Param!$B$5),0) -> 0.89024315 | H10: =IF(Matrice_OD!H10<=Param!$B$2,EXP(-(Matrice_OD!H10^2)/Param!$B$5),0) -> 0.9285353 | I10: =IF(Matrice_OD!I10<=Param!$B$2,EXP(-(Matrice_OD!I10^2)/Param!$B$5),0) -> 0.90459611 | J10: =IF(Matrice_OD!J10<=Param!$B$2,EXP(-(Matrice_OD!J10^2)/Param!$B$5),0) -> 0.89724202 | ... AN10: =IF(Matrice_OD!AN10<=Param!$B$2,EXP(-(Matrice_OD!AN10^2)/Param!$B$5),0) -> 0
A11: 05.091.03.11. | B11: Commune de Foum El Anceur | C11: =IF(Matrice_OD!C11<=Param!$B$2,EXP(-(Matrice_OD!C11^2)/Param!$B$5),0) -> 0.10471285 | D11: =IF(Matrice_OD!D11<=Param!$B$2,EXP(-(Matrice_OD!D11^2)/Param!$B$5),0) -> 0.66069345 | E11: =IF(Matrice_OD!E11<=Param!$B$2,EXP(-(Matrice_OD!E11^2)/Param!$B$5),0) -> 0.66069345 | F11: =IF(Matrice_OD!F11<=Param!$B$2,EXP(-(Matrice_OD!F11^2)/Param!$B$5),0) -> 0.68090484 | G11: =IF(Matrice_OD!G11<=Param!$B$2,EXP(-(Matrice_OD!G11^2)/Param!$B$5),0) -> 0.72073859 | H11: =IF(Matrice_OD!H11<=Param!$B$2,EXP(-(Matrice_OD!H11^2)/Param!$B$5),0) -> 0.68090484 | I11: =IF(Matrice_OD!I11<=Param!$B$2,EXP(-(Matrice_OD!I11^2)/Param!$B$5),0) -> 0.74025733 | J11: =IF(Matrice_OD!J11<=Param!$B$2,EXP(-(Matrice_OD!J11^2)/Param!$B$5),0) -> 0.72073859 | ... AN11: =IF(Matrice_OD!AN11<=Param!$B$2,EXP(-(Matrice_OD!AN11^2)/Param!$B$5),0) -> 0
A12: 05.091.07.11. | B12: Commune de Naour | C12: =IF(Matrice_OD!C12<=Param!$B$2,EXP(-(Matrice_OD!C12^2)/Param!$B$5),0) -> 0 | D12: =IF(Matrice_OD!D12<=Param!$B$2,EXP(-(Matrice_OD!D12^2)/Param!$B$5),0) -> 0 | E12: =IF(Matrice_OD!E12<=Param!$B$2,EXP(-(Matrice_OD!E12^2)/Param!$B$5),0) -> 0 | F12: =IF(Matrice_OD!F12<=Param!$B$2,EXP(-(Matrice_OD!F12^2)/Param!$B$5),0) -> 0 | G12: =IF(Matrice_OD!G12<=Param!$B$2,EXP(-(Matrice_OD!G12^2)/Param!$B$5),0) -> 0 | H12: =IF(Matrice_OD!H12<=Param!$B$2,EXP(-(Matrice_OD!H12^2)/Param!$B$5),0) -> 0 | I12: =IF(Matrice_OD!I12<=Param!$B$2,EXP(-(Matrice_OD!I12^2)/Param!$B$5),0) -> 0 | J12: =IF(Matrice_OD!J12<=Param!$B$2,EXP(-(Matrice_OD!J12^2)/Param!$B$5),0) -> 0 | ... AN12: =IF(Matrice_OD!AN12<=Param!$B$2,EXP(-(Matrice_OD!AN12^2)/Param!$B$5),0) -> 0
A13: 05.091.07.07. | B13: Commune de Dir El Ksiba | C13: =IF(Matrice_OD!C13<=Param!$B$2,EXP(-(Matrice_OD!C13^2)/Param!$B$5),0) -> 0.01055568 | D13: =IF(Matrice_OD!D13<=Param!$B$2,EXP(-(Matrice_OD!D13^2)/Param!$B$5),0) -> 0.14194126 | E13: =IF(Matrice_OD!E13<=Param!$B$2,EXP(-(Matrice_OD!E13^2)/Param!$B$5),0) -> 0.14470381 | F13: =IF(Matrice_OD!F13<=Param!$B$2,EXP(-(Matrice_OD!F13^2)/Param!$B$5),0) -> 0.1473115 | G13: =IF(Matrice_OD!G13<=Param!$B$2,EXP(-(Matrice_OD!G13^2)/Param!$B$5),0) -> 0.14451202 | H13: =IF(Matrice_OD!H13<=Param!$B$2,EXP(-(Matrice_OD!H13^2)/Param!$B$5),0) -> 0.16739481 | I13: =IF(Matrice_OD!I13<=Param!$B$2,EXP(-(Matrice_OD!I13^2)/Param!$B$5),0) -> 0.16527012 | J13: =IF(Matrice_OD!J13<=Param!$B$2,EXP(-(Matrice_OD!J13^2)/Param!$B$5),0) -> 0.15788492 | ... AN13: =IF(Matrice_OD!AN13<=Param!$B$2,EXP(-(Matrice_OD!AN13^2)/Param!$B$5),0) -> 0
... A136: 05.311.07.13. | B136: Commune d'Oulad Aissa | C136: =IF(Matrice_OD!C136<=Param!$B$2,EXP(-(Matrice_OD!C136^2)/Param!$B$5),0) -> 0 | D136: =IF(Matrice_OD!D136<=Param!$B$2,EXP(-(Matrice_OD!D136^2)/Param!$B$5),0) -> 0 | E136: =IF(Matrice_OD!E136<=Param!$B$2,EXP(-(Matrice_OD!E136^2)/Param!$B$5),0) -> 0 | F136: =IF(Matrice_OD!F136<=Param!$B$2,EXP(-(Matrice_OD!F136^2)/Param!$B$5),0) -> 0 | G136: =IF(Matrice_OD!G136<=Param!$B$2,EXP(-(Matrice_OD!G136^2)/Param!$B$5),0) -> 0 | H136: =IF(Matrice_OD!H136<=Param!$B$2,EXP(-(Matrice_OD!H136^2)/Param!$B$5),0) -> 0 | I136: =IF(Matrice_OD!I136<=Param!$B$2,EXP(-(Matrice_OD!I136^2)/Param!$B$5),0) -> 0 | J136: =IF(Matrice_OD!J136<=Param!$B$2,EXP(-(Matrice_OD!J136^2)/Param!$B$5),0) -> 0 | ... AN136: =IF(Matrice_OD!AN136<=Param!$B$2,EXP(-(Matrice_OD!AN136^2)/Param!$B$5),0) -> 0
A137: FEUILLE 1_FRICTION — Étape préliminaire : Fonction de décroissance gaussienne f(dij ; β)
A138: f(dij ; β) = exp(−dij² / β) si dij ≤ dmax , sinon f = 0
A139: • Référence : Subal et al. (2021, p. 6) ; Jörg et al. (2019, p. 29). Fonction gaussienne continue.
A140: • Propriétés clés : f(0) = 1 (accessibilité maximale) ; f(dmax) ≈ 0,01 (quasi-nul au seuil).
A141: • β est calculé automatiquement dans Param!B5 via β = −dmax²/ln(seuil) pour garantir f(dmax)=seuil.
A142: • Interprétation : f(dij) mesure la pénalisation de la distance réelle — plus dij est grand, plus le poids est faible.
A143: • Formule Excel en C2 : =IF(Matrice_OD!C2<=Param!$B$2, EXP(-(Matrice_OD!C2^2)/Param!$B$5), 0)
A144: • ⚠ Contrairement à la 2SFCA binaire, f(d) est CONTINUE : pas de discontinuité à la frontière dmax.
A145: • Cette feuille est référencée par 2_Utilité et 4_SPAI. Ne pas la modifier manuellement.

Sheet 2_Utilité
A1: Code géo. | B1: Commune | C1: DAR ESSALAM - Fkih Ben Saleh | D1: NOUR - Beni Mellal | E1: HÃ´pital PrivÃ© Al-Farabi - Beni Mellal | F1: BEN ASSOU - Beni Mellal | G1: JABRANE - Beni Mellal | H1: BOUHOU - Beni Mellal | I1: BENI MELLAL - Beni Mellal | J1: MALAK - Beni Mellal | K1: ERRAZI - Beni Mellal | L1: AL CHIFA - Beni Mellal | M1: Clinique International Beni Mellal - Beni Mellal | N1: AL ADDARISSA - Beni Mellal | O1: ATLAS - Beni Mellal | P1: ASSALAM - Beni Mellal | Q1: HÃ´pital PrivÃ© de Beni Mellal (Akdital) - Beni Mellal | R1: AMAL - Beni Mellal | S1: IBN SINA - Beni Mellal | T1: LES OLIVIERS YASMINE - Fkih Ben Saleh | U1: Le Lac - Khouribga | V1: Clinique multidisciplinaire-OCP - Khouribga | W1: MARJANE - Khouribga | X1: CHIFA - Khouribga | Y1: DAKHLA - Khouribga | Z1: MOULAY YOUSSEF - Khouribga | AA1: Akdital - Khouribga | AB1: Al Ikhwa - Khouribga | AC1: M. D'ACCOUCHEMENT - Khenifra | AD1: EL AMAL - Khenifra | AE1: ACHIFFA (KARRAOUA) - Khenifra | AF1: LE CEDRE - Khenifra | AG1: Hôpital Provincial d'Azilal | AH1: Hôpital Régional de Béni Mellal | AI1: Hôpital Provincial de Fkih Ben Saleh | AJ1: Hôpital Hassan II (CHP) | AK1: Hôpital Provincial de Khénifra | AL1: CLINIQUE PRIVÉE - Khénifra (Simulation) | AM1: CLINIQUE PRIVÉE - Souk Sebt (Simulation) | AN1: CLINIQUE PRIVÉE - Demnate (Simulation) | AO1: Somme
A2: 05.091.01.01. | B2: Commune de Béni Mellal | C2: =Offre!$E$2*(Offre!$C$2^Param!$B$3)*1_Friction!C2 -> 6.900739 | D2: =Offre!$E$3*(Offre!$C$3^Param!$B$3)*1_Friction!D2 -> 8.8678898 | E2: =Offre!$E$4*(Offre!$C$4^Param!$B$3)*1_Friction!E2 -> 98.594541 | F2: =Offre!$E$5*(Offre!$C$5^Param!$B$3)*1_Friction!F2 -> 17.864917 | G2: =Offre!$E$6*(Offre!$C$6^Param!$B$3)*1_Friction!G2 -> 51.011414 | H2: =Offre!$E$7*(Offre!$C$7^Param!$B$3)*1_Friction!H2 -> 11.614108 | I2: =Offre!$E$8*(Offre!$C$8^Param!$B$3)*1_Friction!I2 -> 26.911725 | J2: =Offre!$E$9*(Offre!$C$9^Param!$B$3)*1_Friction!J2 -> 21.481548 | K2: =Offre!$E$10*(Offre!$C$10^Param!$B$3)*1_Friction!K2 -> 13.48061 | L2: =Offre!$E$11*(Offre!$C$11^Param!$B$3)*1_Friction!L2 -> 13.476246 | M2: =Offre!$E$12*(Offre!$C$12^Param!$B$3)*1_Friction!M2 -> 71.334968 | N2: =Offre!$E$13*(Offre!$C$13^Param!$B$3)*1_Friction!N2 -> 9.8094571 | O2: =Offre!$E$14*(Offre!$C$14^Param!$B$3)*1_Friction!O2 -> 31.44267 | P2: =Offre!$E$15*(Offre!$C$15^Param!$B$3)*1_Friction!P2 -> 15.254053 | Q2: =Offre!$E$16*(Offre!$C$16^Param!$B$3)*1_Friction!Q2 -> 134.66515 | R2: =Offre!$E$17*(Offre!$C$17^Param!$B$3)*1_Friction!R2 -> 17.931482 | S2: =Offre!$E$18*(Offre!$C$18^Param!$B$3)*1_Friction!S2 -> 13.451731 | T2: =Offre!$E$19*(Offre!$C$19^Param!$B$3)*1_Friction!T2 -> 5.7168076 | U2: =Offre!$E$20*(Offre!$C$20^Param!$B$3)*1_Friction!U2 -> 5.038853 | V2: =Offre!$E$21*(Offre!$C$21^Param!$B$3)*1_Friction!V2 -> 4.3782455 | W2: =Offre!$E$22*(Offre!$C$22^Param!$B$3)*1_Friction!W2 -> 0.73767316 | X2: =Offre!$E$23*(Offre!$C$23^Param!$B$3)*1_Friction!X2 -> 1.1303029 | Y2: =Offre!$E$24*(Offre!$C$24^Param!$B$3)*1_Friction!Y2 -> 0.75225592 | Z2: =Offre!$E$25*(Offre!$C$25^Param!$B$3)*1_Friction!Z2 -> 1.8347749 | AA2: =Offre!$E$26*(Offre!$C$26^Param!$B$3)*1_Friction!AA2 -> 3.8353978 | AB2: =Offre!$E$27*(Offre!$C$27^Param!$B$3)*1_Friction!AB2 -> 1.9138206 | AC2: =Offre!$E$28*(Offre!$C$28^Param!$B$3)*1_Friction!AC2 -> 0 | AD2: =Offre!$E$29*(Offre!$C$29^Param!$B$3)*1_Friction!AD2 -> 0 | AE2: =Offre!$E$30*(Offre!$C$30^Param!$B$3)*1_Friction!AE2 -> 0 | AF2: =Offre!$E$31*(Offre!$C$31^Param!$B$3)*1_Friction!AF2 -> 0 | AG2: =Offre!$E$32*(Offre!$C$32^Param!$B$3)*1_Friction!AG2 -> 0 | AH2: =Offre!$E$33*(Offre!$C$33^Param!$B$3)*1_Friction!AH2 -> 44.228643 | AI2: =Offre!$E$34*(Offre!$C$34^Param!$B$3)*1_Friction!AI2 -> 2.5108014 | AJ2: =Offre!$E$35*(Offre!$C$35^Param!$B$3)*1_Friction!AJ2 -> 1.5961614 | AK2: =Offre!$E$36*(Offre!$C$36^Param!$B$3)*1_Friction!AK2 -> 0 | AL2: =Offre!$E$37*(Offre!$C$37^Param!$B$3)*1_Friction!AL2 -> 0 | AM2: =Offre!$E$38*(Offre!$C$38^Param!$B$3)*1_Friction!AM2 -> 16.114839 | AN2: =Offre!$E$39*(Offre!$C$39^Param!$B$3)*1_Friction!AN2 -> 0 | AO2: =SUM(C2:AN2) -> 653.88183
A3: 05.091.01.07. | B3: Commune de Kasba Tadla | C3: =Offre!$E$2*(Offre!$C$2^Param!$B$3)*1_Friction!C3 -> 0.86161746 | D3: =Offre!$E$3*(Offre!$C$3^Param!$B$3)*1_Friction!D3 -> 3.6074723 | E3: =Offre!$E$4*(Offre!$C$4^Param!$B$3)*1_Friction!E3 -> 40.57401 | F3: =Offre!$E$5*(Offre!$C$5^Param!$B$3)*1_Friction!F3 -> 7.4002254 | G3: =Offre!$E$6*(Offre!$C$6^Param!$B$3)*1_Friction!G3 -> 20.825872 | H3: =Offre!$E$7*(Offre!$C$7^Param!$B$3)*1_Friction!H3 -> 5.2462821 | I3: =Offre!$E$8*(Offre!$C$8^Param!$B$3)*1_Friction!I3 -> 12.003559 | J3: =Offre!$E$9*(Offre!$C$9^Param!$B$3)*1_Friction!J3 -> 9.3118559 | K3: =Offre!$E$10*(Offre!$C$10^Param!$B$3)*1_Friction!K3 -> 5.6378049 | L3: =Offre!$E$11*(Offre!$C$11^Param!$B$3)*1_Friction!L3 -> 6.0069343 | M3: =Offre!$E$12*(Offre!$C$12^Param!$B$3)*1_Friction!M3 -> 33.716378 | N3: =Offre!$E$13*(Offre!$C$13^Param!$B$3)*1_Friction!N3 -> 4.2997196 | O3: =Offre!$E$14*(Offre!$C$14^Param!$B$3)*1_Friction!O3 -> 13.782362 | P3: =Offre!$E$15*(Offre!$C$15^Param!$B$3)*1_Friction!P3 -> 6.8020168 | Q3: =Offre!$E$16*(Offre!$C$16^Param!$B$3)*1_Friction!Q3 -> 60.2757 | R3: =Offre!$E$17*(Offre!$C$17^Param!$B$3)*1_Friction!R3 -> 7.968042 | S3: =Offre!$E$18*(Offre!$C$18^Param!$B$3)*1_Friction!S3 -> 5.8250025 | T3: =Offre!$E$19*(Offre!$C$19^Param!$B$3)*1_Friction!T3 -> 4.8573835 | U3: =Offre!$E$20*(Offre!$C$20^Param!$B$3)*1_Friction!U3 -> 7.7915818 | V3: =Offre!$E$21*(Offre!$C$21^Param!$B$3)*1_Friction!V3 -> 6.3629518 | W3: =Offre!$E$22*(Offre!$C$22^Param!$B$3)*1_Friction!W3 -> 1.4198707 | X3: =Offre!$E$23*(Offre!$C$23^Param!$B$3)*1_Friction!X3 -> 2.1488868 | Y3: =Offre!$E$24*(Offre!$C$24^Param!$B$3)*1_Friction!Y3 -> 1.4315047 | Z3: =Offre!$E$25*(Offre!$C$25^Param!$B$3)*1_Friction!Z3 -> 3.5007059 | AA3: =Offre!$E$26*(Offre!$C$26^Param!$B$3)*1_Friction!AA3 -> 7.2778066 | AB3: =Offre!$E$27*(Offre!$C$27^Param!$B$3)*1_Friction!AB3 -> 3.5911879 | AC3: =Offre!$E$28*(Offre!$C$28^Param!$B$3)*1_Friction!AC3 -> 0 | AD3: =Offre!$E$29*(Offre!$C$29^Param!$B$3)*1_Friction!AD3 -> 0 | AE3: =Offre!$E$30*(Offre!$C$30^Param!$B$3)*1_Friction!AE3 -> 0 | AF3: =Offre!$E$31*(Offre!$C$31^Param!$B$3)*1_Friction!AF3 -> 0 | AG3: =Offre!$E$32*(Offre!$C$32^Param!$B$3)*1_Friction!AG3 -> 0 | AH3: =Offre!$E$33*(Offre!$C$33^Param!$B$3)*1_Friction!AH3 -> 20.510572 | AI3: =Offre!$E$34*(Offre!$C$34^Param!$B$3)*1_Friction!AI3 -> 2.1257488 | AJ3: =Offre!$E$35*(Offre!$C$35^Param!$B$3)*1_Friction!AJ3 -> 3.0604336 | AK3: =Offre!$E$36*(Offre!$C$36^Param!$B$3)*1_Friction!AK3 -> 0 | AL3: =Offre!$E$37*(Offre!$C$37^Param!$B$3)*1_Friction!AL3 -> 0 | AM3: =Offre!$E$38*(Offre!$C$38^Param!$B$3)*1_Friction!AM3 -> 2.0001861 | AN3: =Offre!$E$39*(Offre!$C$39^Param!$B$3)*1_Friction!AN3 -> 0 | AO3: =SUM(C3:AN3) -> 310.22367
A4: 05.091.01.13. | B4: Commune de Zaouiat Cheikh | C4: =Offre!$E$2*(Offre!$C$2^Param!$B$3)*1_Friction!C4 -> 0 | D4: =Offre!$E$3*(Offre!$C$3^Param!$B$3)*1_Friction!D4 -> 0.87358189 | E4: =Offre!$E$4*(Offre!$C$4^Param!$B$3)*1_Friction!E4 -> 9.8960878 | F4: =Offre!$E$5*(Offre!$C$5^Param!$B$3)*1_Friction!F4 -> 1.81957 | G4: =Offre!$E$6*(Offre!$C$6^Param!$B$3)*1_Friction!G4 -> 5.078091 | H4: =Offre!$E$7*(Offre!$C$7^Param!$B$3)*1_Friction!H4 -> 1.3604716 | I4: =Offre!$E$8*(Offre!$C$8^Param!$B$3)*1_Friction!I4 -> 3.0958609 | J4: =Offre!$E$9*(Offre!$C$9^Param!$B$3)*1_Friction!J4 -> 2.3556288 | K4: =Offre!$E$10*(Offre!$C$10^Param!$B$3)*1_Friction!K4 -> 1.398497 | L4: =Offre!$E$11*(Offre!$C$11^Param!$B$3)*1_Friction!L4 -> 1.5501043 | M4: =Offre!$E$12*(Offre!$C$12^Param!$B$3)*1_Friction!M4 -> 8.9921968 | N4: =Offre!$E$13*(Offre!$C$13^Param!$B$3)*1_Friction!N4 -> 1.0935273 | O4: =Offre!$E$14*(Offre!$C$14^Param!$B$3)*1_Friction!O4 -> 3.5189832 | P4: =Offre!$E$15*(Offre!$C$15^Param!$B$3)*1_Friction!P4 -> 1.7543212 | Q4: =Offre!$E$16*(Offre!$C$16^Param!$B$3)*1_Friction!Q4 -> 15.588233 | R4: =Offre!$E$17*(Offre!$C$17^Param!$B$3)*1_Friction!R4 -> 2.0509028 | S4: =Offre!$E$18*(Offre!$C$18^Param!$B$3)*1_Friction!S4 -> 1.475406 | T4: =Offre!$E$19*(Offre!$C$19^Param!$B$3)*1_Friction!T4 -> 0.76442597 | U4: =Offre!$E$20*(Offre!$C$20^Param!$B$3)*1_Friction!U4 -> 1.2160338 | V4: =Offre!$E$21*(Offre!$C$21^Param!$B$3)*1_Friction!V4 -> 0 | W4: =Offre!$E$22*(Offre!$C$22^Param!$B$3)*1_Friction!W4 -> 0 | X4: =Offre!$E$23*(Offre!$C$23^Param!$B$3)*1_Friction!X4 -> 0 | Y4: =Offre!$E$24*(Offre!$C$24^Param!$B$3)*1_Friction!Y4 -> 0 | Z4: =Offre!$E$25*(Offre!$C$25^Param!$B$3)*1_Friction!Z4 -> 0 | AA4: =Offre!$E$26*(Offre!$C$26^Param!$B$3)*1_Friction!AA4 -> 0 | AB4: =Offre!$E$27*(Offre!$C$27^Param!$B$3)*1_Friction!AB4 -> 0 | AC4: =Offre!$E$28*(Offre!$C$28^Param!$B$3)*1_Friction!AC4 -> 0.49950931 | AD4: =Offre!$E$29*(Offre!$C$29^Param!$B$3)*1_Friction!AD4 -> 2.4263435 | AE4: =Offre!$E$30*(Offre!$C$30^Param!$B$3)*1_Friction!AE4 -> 1.3768807 | AF4: =Offre!$E$31*(Offre!$C$31^Param!$B$3)*1_Friction!AF4 -> 0.91227958 | AG4: =Offre!$E$32*(Offre!$C$32^Param!$B$3)*1_Friction!AG4 -> 0 | AH4: =Offre!$E$33*(Offre!$C$33^Param!$B$3)*1_Friction!AH4 -> 5.413853 | AI4: =Offre!$E$34*(Offre!$C$34^Param!$B$3)*1_Friction!AI4 -> 0.32456445 | AJ4: =Offre!$E$35*(Offre!$C$35^Param!$B$3)*1_Friction!AJ4 -> 0 | AK4: =Offre!$E$36*(Offre!$C$36^Param!$B$3)*1_Friction!AK4 -> 2.3514707 | AL4: =Offre!$E$37*(Offre!$C$37^Param!$B$3)*1_Friction!AL4 -> 4.5864621 | AM4: =Offre!$E$38*(Offre!$C$38^Param!$B$3)*1_Friction!AM4 -> 0 | AN4: =Offre!$E$39*(Offre!$C$39^Param!$B$3)*1_Friction!AN4 -> 0 | AO4: =SUM(C4:AN4) -> 81.773286
A5: 05.091.01.03. | B5: Commune d'El Ksiba | C5: =Offre!$E$2*(Offre!$C$2^Param!$B$3)*1_Friction!C5 -> 0.14863344 | D5: =Offre!$E$3*(Offre!$C$3^Param!$B$3)*1_Friction!D5 -> 1.2588465 | E5: =Offre!$E$4*(Offre!$C$4^Param!$B$3)*1_Friction!E5 -> 14.246186 | F5: =Offre!$E$5*(Offre!$C$5^Param!$B$3)*1_Friction!F5 -> 2.6133141 | G5: =Offre!$E$6*(Offre!$C$6^Param!$B$3)*1_Friction!G5 -> 7.3107413 | H5: =Offre!$E$7*(Offre!$C$7^Param!$B$3)*1_Friction!H5 -> 1.9324235 | I5: =Offre!$E$8*(Offre!$C$8^Param!$B$3)*1_Friction!I5 -> 4.3997994 | J5: =Offre!$E$9*(Offre!$C$9^Param!$B$3)*1_Friction!J5 -> 3.3641431 | K5: =Offre!$E$10*(Offre!$C$10^Param!$B$3)*1_Friction!K5 -> 2.0058214 | L5: =Offre!$E$11*(Offre!$C$11^Param!$B$3)*1_Friction!L5 -> 2.2041419 | M5: =Offre!$E$12*(Offre!$C$12^Param!$B$3)*1_Friction!M5 -> 12.694435 | N5: =Offre!$E$13*(Offre!$C$13^Param!$B$3)*1_Friction!N5 -> 1.5590136 | O5: =Offre!$E$14*(Offre!$C$14^Param!$B$3)*1_Friction!O5 -> 5.0153933 | P5: =Offre!$E$15*(Offre!$C$15^Param!$B$3)*1_Friction!P5 -> 2.4948215 | Q5: =Offre!$E$16*(Offre!$C$16^Param!$B$3)*1_Friction!Q5 -> 22.154833 | R5: =Offre!$E$17*(Offre!$C$17^Param!$B$3)*1_Friction!R5 -> 2.9162782 | S5: =Offre!$E$18*(Offre!$C$18^Param!$B$3)*1_Friction!S5 -> 2.1053254 | T5: =Offre!$E$19*(Offre!$C$19^Param!$B$3)*1_Friction!T5 -> 1.0682945 | U5: =Offre!$E$20*(Offre!$C$20^Param!$B$3)*1_Friction!U5 -> 1.7015433 | V5: =Offre!$E$21*(Offre!$C$21^Param!$B$3)*1_Friction!V5 -> 0 | W5: =Offre!$E$22*(Offre!$C$22^Param!$B$3)*1_Friction!W5 -> 0 | X5: =Offre!$E$23*(Offre!$C$23^Param!$B$3)*1_Friction!X5 -> 0 | Y5: =Offre!$E$24*(Offre!$C$24^Param!$B$3)*1_Friction!Y5 -> 0 | Z5: =Offre!$E$25*(Offre!$C$25^Param!$B$3)*1_Friction!Z5 -> 0 | AA5: =Offre!$E$26*(Offre!$C$26^Param!$B$3)*1_Friction!AA5 -> 0 | AB5: =Offre!$E$27*(Offre!$C$27^Param!$B$3)*1_Friction!AB5 -> 0.43939241 | AC5: =Offre!$E$28*(Offre!$C$28^Param!$B$3)*1_Friction!AC5 -> 0.099473933 | AD5: =Offre!$E$29*(Offre!$C$29^Param!$B$3)*1_Friction!AD5 -> 0.47836872 | AE5: =Offre!$E$30*(Offre!$C$30^Param!$B$3)*1_Friction!AE5 -> 0.26631862 | AF5: =Offre!$E$31*(Offre!$C$31^Param!$B$3)*1_Friction!AF5 -> 0.17608469 | AG5: =Offre!$E$32*(Offre!$C$32^Param!$B$3)*1_Friction!AG5 -> 0 | AH5: =Offre!$E$33*(Offre!$C$33^Param!$B$3)*1_Friction!AH5 -> 7.6553064 | AI5: =Offre!$E$34*(Offre!$C$34^Param!$B$3)*1_Friction!AI5 -> 0.45596675 | AJ5: =Offre!$E$35*(Offre!$C$35^Param!$B$3)*1_Friction!AJ5 -> 0 | AK5: =Offre!$E$36*(Offre!$C$36^Param!$B$3)*1_Friction!AK5 -> 0.40893972 | AL5: =Offre!$E$37*(Offre!$C$37^Param!$B$3)*1_Friction!AL5 -> 0.88772874 | AM5: =Offre!$E$38*(Offre!$C$38^Param!$B$3)*1_Friction!AM5 -> 0 | AN5: =Offre!$E$39*(Offre!$C$39^Param!$B$3)*1_Friction!AN5 -> 0 | AO5: =SUM(C5:AN5) -> 102.06157
A6: 05.091.03.03. | B6: Commune d'Ouled Gnaou | C6: =Offre!$E$2*(Offre!$C$2^Param!$B$3)*1_Friction!C6 -> 9.3179059 | D6: =Offre!$E$3*(Offre!$C$3^Param!$B$3)*1_Friction!D6 -> 6.8622777 | E6: =Offre!$E$4*(Offre!$C$4^Param!$B$3)*1_Friction!E6 -> 73.486583 | F6: =Offre!$E$5*(Offre!$C$5^Param!$B$3)*1_Friction!F6 -> 13.335084 | G6: =Offre!$E$6*(Offre!$C$6^Param!$B$3)*1_Friction!G6 -> 37.094866 | H6: =Offre!$E$7*(Offre!$C$7^Param!$B$3)*1_Friction!H6 -> 9.1075309 | I6: =Offre!$E$8*(Offre!$C$8^Param!$B$3)*1_Friction!I6 -> 20.060039 | J6: =Offre!$E$9*(Offre!$C$9^Param!$B$3)*1_Friction!J6 -> 15.825932 | K6: =Offre!$E$10*(Offre!$C$10^Param!$B$3)*1_Friction!K6 -> 9.8411481 | L6: =Offre!$E$11*(Offre!$C$11^Param!$B$3)*1_Friction!L6 -> 10.037839 | M6: =Offre!$E$12*(Offre!$C$12^Param!$B$3)*1_Friction!M6 -> 55.034411 | N6: =Offre!$E$13*(Offre!$C$13^Param!$B$3)*1_Friction!N6 -> 7.3400413 | O6: =Offre!$E$14*(Offre!$C$14^Param!$B$3)*1_Friction!O6 -> 23.18369 | P6: =Offre!$E$15*(Offre!$C$15^Param!$B$3)*1_Friction!P6 -> 11.233871 | Q6: =Offre!$E$16*(Offre!$C$16^Param!$B$3)*1_Friction!Q6 -> 98.226676 | R6: =Offre!$E$17*(Offre!$C$17^Param!$B$3)*1_Friction!R6 -> 13.051059 | S6: =Offre!$E$18*(Offre!$C$18^Param!$B$3)*1_Friction!S6 -> 9.7140324 | T6: =Offre!$E$19*(Offre!$C$19^Param!$B$3)*1_Friction!T6 -> 5.4678438 | U6: =Offre!$E$20*(Offre!$C$20^Param!$B$3)*1_Friction!U6 -> 1.5303274 | V6: =Offre!$E$21*(Offre!$C$21^Param!$B$3)*1_Friction!V6 -> 4.034697 | W6: =Offre!$E$22*(Offre!$C$22^Param!$B$3)*1_Friction!W6 -> 0.65108921 | X6: =Offre!$E$23*(Offre!$C$23^Param!$B$3)*1_Friction!X6 -> 0.879278 | Y6: =Offre!$E$24*(Offre!$C$24^Param!$B$3)*1_Friction!Y6 -> 0.58515151 | Z6: =Offre!$E$25*(Offre!$C$25^Param!$B$3)*1_Friction!Z6 -> 1.425838 | AA6: =Offre!$E$26*(Offre!$C$26^Param!$B$3)*1_Friction!AA6 -> 2.5048775 | AB6: =Offre!$E$27*(Offre!$C$27^Param!$B$3)*1_Friction!AB6 -> 1.0550062 | AC6: =Offre!$E$28*(Offre!$C$28^Param!$B$3)*1_Friction!AC6 -> 0 | AD6: =Offre!$E$29*(Offre!$C$29^Param!$B$3)*1_Friction!AD6 -> 0 | AE6: =Offre!$E$30*(Offre!$C$30^Param!$B$3)*1_Friction!AE6 -> 0 | AF6: =Offre!$E$31*(Offre!$C$31^Param!$B$3)*1_Friction!AF6 -> 0 | AG6: =Offre!$E$32*(Offre!$C$32^Param!$B$3)*1_Friction!AG6 -> 0.13876715 | AH6: =Offre!$E$33*(Offre!$C$33^Param!$B$3)*1_Friction!AH6 -> 31.333435 | AI6: =Offre!$E$34*(Offre!$C$34^Param!$B$3)*1_Friction!AI6 -> 2.5521623 | AJ6: =Offre!$E$35*(Offre!$C$35^Param!$B$3)*1_Friction!AJ6 -> 1.2382002 | AK6: =Offre!$E$36*(Offre!$C$36^Param!$B$3)*1_Friction!AK6 -> 0 | AL6: =Offre!$E$37*(Offre!$C$37^Param!$B$3)*1_Friction!AL6 -> 0 | AM6: =Offre!$E$38*(Offre!$C$38^Param!$B$3)*1_Friction!AM6 -> 22.611901 | AN6: =Offre!$E$39*(Offre!$C$39^Param!$B$3)*1_Friction!AN6 -> 0 | AO6: =SUM(C6:AN6) -> 498.76156
A7: 05.091.03.05. | B7: Commune d'Ouled M'barek | C7: =Offre!$E$2*(Offre!$C$2^Param!$B$3)*1_Friction!C7 -> 10.715364 | D7: =Offre!$E$3*(Offre!$C$3^Param!$B$3)*1_Friction!D7 -> 7.9833583 | E7: =Offre!$E$4*(Offre!$C$4^Param!$B$3)*1_Friction!E7 -> 86.242618 | F7: =Offre!$E$5*(Offre!$C$5^Param!$B$3)*1_Friction!F7 -> 15.507882 | G7: =Offre!$E$6*(Offre!$C$6^Param!$B$3)*1_Friction!G7 -> 43.761339 | H7: =Offre!$E$7*(Offre!$C$7^Param!$B$3)*1_Friction!H7 -> 9.8557088 | I7: =Offre!$E$8*(Offre!$C$8^Param!$B$3)*1_Friction!I7 -> 22.685402 | J7: =Offre!$E$9*(Offre!$C$9^Param!$B$3)*1_Friction!J7 -> 18.03573 | K7: =Offre!$E$10*(Offre!$C$10^Param!$B$3)*1_Friction!K7 -> 11.228811 | L7: =Offre!$E$11*(Offre!$C$11^Param!$B$3)*1_Friction!L7 -> 11.210399 | M7: =Offre!$E$12*(Offre!$C$12^Param!$B$3)*1_Friction!M7 -> 59.751902 | N7: =Offre!$E$13*(Offre!$C$13^Param!$B$3)*1_Friction!N7 -> 8.1665783 | O7: =Offre!$E$14*(Offre!$C$14^Param!$B$3)*1_Friction!O7 -> 25.951915 | P7: =Offre!$E$15*(Offre!$C$15^Param!$B$3)*1_Friction!P7 -> 12.578713 | Q7: =Offre!$E$16*(Offre!$C$16^Param!$B$3)*1_Friction!Q7 -> 110.21154 | R7: =Offre!$E$17*(Offre!$C$17^Param!$B$3)*1_Friction!R7 -> 14.653756 | S7: =Offre!$E$18*(Offre!$C$18^Param!$B$3)*1_Friction!S7 -> 10.923478 | T7: =Offre!$E$19*(Offre!$C$19^Param!$B$3)*1_Friction!T7 -> 4.7565382 | U7: =Offre!$E$20*(Offre!$C$20^Param!$B$3)*1_Friction!U7 -> 1.8539066 | V7: =Offre!$E$21*(Offre!$C$21^Param!$B$3)*1_Friction!V7 -> 3.1377093 | W7: =Offre!$E$22*(Offre!$C$22^Param!$B$3)*1_Friction!W7 -> 0.50277107 | X7: =Offre!$E$23*(Offre!$C$23^Param!$B$3)*1_Friction!X7 -> 0.6787339 | Y7: =Offre!$E$24*(Offre!$C$24^Param!$B$3)*1_Friction!Y7 -> 0.45166165 | Z7: =Offre!$E$25*(Offre!$C$25^Param!$B$3)*1_Friction!Z7 -> 1.0995187 | AA7: =Offre!$E$26*(Offre!$C$26^Param!$B$3)*1_Friction!AA7 -> 1.9224573 | AB7: =Offre!$E$27*(Offre!$C$27^Param!$B$3)*1_Friction!AB7 -> 0.80853119 | AC7: =Offre!$E$28*(Offre!$C$28^Param!$B$3)*1_Friction!AC7 -> 0 | AD7: =Offre!$E$29*(Offre!$C$29^Param!$B$3)*1_Friction!AD7 -> 0 | AE7: =Offre!$E$30*(Offre!$C$30^Param!$B$3)*1_Friction!AE7 -> 0 | AF7: =Offre!$E$31*(Offre!$C$31^Param!$B$3)*1_Friction!AF7 -> 0 | AG7: =Offre!$E$32*(Offre!$C$32^Param!$B$3)*1_Friction!AG7 -> 0.43354661 | AH7: =Offre!$E$33*(Offre!$C$33^Param!$B$3)*1_Friction!AH7 -> 35.38367 | AI7: =Offre!$E$34*(Offre!$C$34^Param!$B$3)*1_Friction!AI7 -> 2.0796352 | AJ7: =Offre!$E$35*(Offre!$C$35^Param!$B$3)*1_Friction!AJ7 -> 0.95313697 | AK7: =Offre!$E$36*(Offre!$C$36^Param!$B$3)*1_Friction!AK7 -> 0 | AL7: =Offre!$E$37*(Offre!$C$37^Param!$B$3)*1_Friction!AL7 -> 0 | AM7: =Offre!$E$38*(Offre!$C$38^Param!$B$3)*1_Friction!AM7 -> 25.662563 | AN7: =Offre!$E$39*(Offre!$C$39^Param!$B$3)*1_Friction!AN7 -> 0 | AO7: =SUM(C7:AN7) -> 559.18888
A8: 05.091.03.01. | B8: Commune de Foum Oudi | C8: =Offre!$E$2*(Offre!$C$2^Param!$B$3)*1_Friction!C8 -> 7.8754339 | D8: =Offre!$E$3*(Offre!$C$3^Param!$B$3)*1_Friction!D8 -> 8.1364416 | E8: =Offre!$E$4*(Offre!$C$4^Param!$B$3)*1_Friction!E8 -> 88.083643 | F8: =Offre!$E$5*(Offre!$C$5^Param!$B$3)*1_Friction!F8 -> 15.841307 | G8: =Offre!$E$6*(Offre!$C$6^Param!$B$3)*1_Friction!G8 -> 44.734562 | H8: =Offre!$E$7*(Offre!$C$7^Param!$B$3)*1_Friction!H8 -> 10.083833 | I8: =Offre!$E$8*(Offre!$C$8^Param!$B$3)*1_Friction!I8 -> 23.214605 | J8: =Offre!$E$9*(Offre!$C$9^Param!$B$3)*1_Friction!J8 -> 18.464274 | K8: =Offre!$E$10*(Offre!$C$10^Param!$B$3)*1_Friction!K8 -> 11.498598 | L8: =Offre!$E$11*(Offre!$C$11^Param!$B$3)*1_Friction!L8 -> 11.480997 | M8: =Offre!$E$12*(Offre!$C$12^Param!$B$3)*1_Friction!M8 -> 61.196703 | N8: =Offre!$E$13*(Offre!$C$13^Param!$B$3)*1_Friction!N8 -> 8.3673567 | O8: =Offre!$E$14*(Offre!$C$14^Param!$B$3)*1_Friction!O8 -> 26.58691 | P8: =Offre!$E$15*(Offre!$C$15^Param!$B$3)*1_Friction!P8 -> 12.89078 | Q8: =Offre!$E$16*(Offre!$C$16^Param!$B$3)*1_Friction!Q8 -> 112.97392 | R8: =Offre!$E$17*(Offre!$C$17^Param!$B$3)*1_Friction!R8 -> 15.026731 | S8: =Offre!$E$18*(Offre!$C$18^Param!$B$3)*1_Friction!S8 -> 11.203482 | T8: =Offre!$E$19*(Offre!$C$19^Param!$B$3)*1_Friction!T8 -> 4.3694492 | U8: =Offre!$E$20*(Offre!$C$20^Param!$B$3)*1_Friction!U8 -> 2.0291102 | V8: =Offre!$E$21*(Offre!$C$21^Param!$B$3)*1_Friction!V8 -> 2.7027833 | W8: =Offre!$E$22*(Offre!$C$22^Param!$B$3)*1_Friction!W8 -> 0.43131854 | X8: =Offre!$E$23*(Offre!$C$23^Param!$B$3)*1_Friction!X8 -> 0.58215311 | Y8: =Offre!$E$24*(Offre!$C$24^Param!$B$3)*1_Friction!Y8 -> 0.38773969 | Z8: =Offre!$E$25*(Offre!$C$25^Param!$B$3)*1_Friction!Z8 -> 0.94339458 | AA8: =Offre!$E$26*(Offre!$C$26^Param!$B$3)*1_Friction!AA8 -> 1.6434316 | AB8: =Offre!$E$27*(Offre!$C$27^Param!$B$3)*1_Friction!AB8 -> 0.69024214 | AC8: =Offre!$E$28*(Offre!$C$28^Param!$B$3)*1_Friction!AC8 -> 0 | AD8: =Offre!$E$29*(Offre!$C$29^Param!$B$3)*1_Friction!AD8 -> 0 | AE8: =Offre!$E$30*(Offre!$C$30^Param!$B$3)*1_Friction!AE8 -> 0 | AF8: =Offre!$E$31*(Offre!$C$31^Param!$B$3)*1_Friction!AF8 -> 0 | AG8: =Offre!$E$32*(Offre!$C$32^Param!$B$3)*1_Friction!AG8 -> 0.18744595 | AH8: =Offre!$E$33*(Offre!$C$33^Param!$B$3)*1_Friction!AH8 -> 36.336792 | AI8: =Offre!$E$34*(Offre!$C$34^Param!$B$3)*1_Friction!AI8 -> 1.9070431 | AJ8: =Offre!$E$35*(Offre!$C$35^Param!$B$3)*1_Friction!AJ8 -> 0.8169699 | AK8: =Offre!$E$36*(Offre!$C$36^Param!$B$3)*1_Friction!AK8 -> 0 | AL8: =Offre!$E$37*(Offre!$C$37^Param!$B$3)*1_Friction!AL8 -> 0 | AM8: =Offre!$E$38*(Offre!$C$38^Param!$B$3)*1_Friction!AM8 -> 18.514096 | AN8: =Offre!$E$39*(Offre!$C$39^Param!$B$3)*1_Friction!AN8 -> 0 | AO8: =SUM(C8:AN8) -> 559.20155
A9: 05.091.03.07. | B9: Commune d'Ouled Yaich | C9: =Offre!$E$2*(Offre!$C$2^Param!$B$3)*1_Friction!C9 -> 3.257332 | D9: =Offre!$E$3*(Offre!$C$3^Param!$B$3)*1_Friction!D9 -> 7.1267658 | E9: =Offre!$E$4*(Offre!$C$4^Param!$B$3)*1_Friction!E9 -> 79.63356 | F9: =Offre!$E$5*(Offre!$C$5^Param!$B$3)*1_Friction!F9 -> 14.436031 | G9: =Offre!$E$6*(Offre!$C$6^Param!$B$3)*1_Friction!G9 -> 40.883622 | H9: =Offre!$E$7*(Offre!$C$7^Param!$B$3)*1_Friction!H9 -> 9.7871308 | I9: =Offre!$E$8*(Offre!$C$8^Param!$B$3)*1_Friction!I9 -> 22.489758 | J9: =Offre!$E$9*(Offre!$C$9^Param!$B$3)*1_Friction!J9 -> 17.73192 | K9: =Offre!$E$10*(Offre!$C$10^Param!$B$3)*1_Friction!K9 -> 10.911483 | L9: =Offre!$E$11*(Offre!$C$11^Param!$B$3)*1_Friction!L9 -> 11.251753 | M9: =Offre!$E$12*(Offre!$C$12^Param!$B$3)*1_Friction!M9 -> 61.454432 | N9: =Offre!$E$13*(Offre!$C$13^Param!$B$3)*1_Friction!N9 -> 8.1563163 | O9: =Offre!$E$14*(Offre!$C$14^Param!$B$3)*1_Friction!O9 -> 26.044259 | P9: =Offre!$E$15*(Offre!$C$15^Param!$B$3)*1_Friction!P9 -> 12.746794 | Q9: =Offre!$E$16*(Offre!$C$16^Param!$B$3)*1_Friction!Q9 -> 112.70048 | R9: =Offre!$E$17*(Offre!$C$17^Param!$B$3)*1_Friction!R9 -> 14.965617 | S9: =Offre!$E$18*(Offre!$C$18^Param!$B$3)*1_Friction!S9 -> 11.087144 | T9: =Offre!$E$19*(Offre!$C$19^Param!$B$3)*1_Friction!T9 -> 4.2453401 | U9: =Offre!$E$20*(Offre!$C$20^Param!$B$3)*1_Friction!U9 -> 7.6558587 | V9: =Offre!$E$21*(Offre!$C$21^Param!$B$3)*1_Friction!V9 -> 6.1881486 | W9: =Offre!$E$22*(Offre!$C$22^Param!$B$3)*1_Friction!W9 -> 1.3818205 | X9: =Offre!$E$23*(Offre!$C$23^Param!$B$3)*1_Friction!X9 -> 2.0924324 | Y9: =Offre!$E$24*(Offre!$C$24^Param!$B$3)*1_Friction!Y9 -> 1.3938914 | Z9: =Offre!$E$25*(Offre!$C$25^Param!$B$3)*1_Friction!Z9 -> 3.4083303 | AA9: =Offre!$E$26*(Offre!$C$26^Param!$B$3)*1_Friction!AA9 -> 7.0872003 | AB9: =Offre!$E$27*(Offre!$C$27^Param!$B$3)*1_Friction!AB9 -> 3.4988468 | AC9: =Offre!$E$28*(Offre!$C$28^Param!$B$3)*1_Friction!AC9 -> 0 | AD9: =Offre!$E$29*(Offre!$C$29^Param!$B$3)*1_Friction!AD9 -> 0 | AE9: =Offre!$E$30*(Offre!$C$30^Param!$B$3)*1_Friction!AE9 -> 0 | AF9: =Offre!$E$31*(Offre!$C$31^Param!$B$3)*1_Friction!AF9 -> 0 | AG9: =Offre!$E$32*(Offre!$C$32^Param!$B$3)*1_Friction!AG9 -> 0 | AH9: =Offre!$E$33*(Offre!$C$33^Param!$B$3)*1_Friction!AH9 -> 37.698911 | AI9: =Offre!$E$34*(Offre!$C$34^Param!$B$3)*1_Friction!AI9 -> 1.8527941 | AJ9: =Offre!$E$35*(Offre!$C$35^Param!$B$3)*1_Friction!AJ9 -> 2.9790355 | AK9: =Offre!$E$36*(Offre!$C$36^Param!$B$3)*1_Friction!AK9 -> 0 | AL9: =Offre!$E$37*(Offre!$C$37^Param!$B$3)*1_Friction!AL9 -> 0 | AM9: =Offre!$E$38*(Offre!$C$38^Param!$B$3)*1_Friction!AM9 -> 7.3781409 | AN9: =Offre!$E$39*(Offre!$C$39^Param!$B$3)*1_Friction!AN9 -> 0 | AO9: =SUM(C9:AN9) -> 551.52515
A10: 05.091.03.09. | B10: Commune de Sidi Jaber | C10: =Offre!$E$2*(Offre!$C$2^Param!$B$3)*1_Friction!C10 -> 6.2895855 | D10: =Offre!$E$3*(Offre!$C$3^Param!$B$3)*1_Friction!D10 -> 8.2616911 | E10: =Offre!$E$4*(Offre!$C$4^Param!$B$3)*1_Friction!E10 -> 89.844708 | F10: =Offre!$E$5*(Offre!$C$5^Param!$B$3)*1_Friction!F10 -> 16.255594 | G10: =Offre!$E$6*(Offre!$C$6^Param!$B$3)*1_Friction!G10 -> 45.669474 | H10: =Offre!$E$7*(Offre!$C$7^Param!$B$3)*1_Friction!H10 -> 10.863863 | I10: =Offre!$E$8*(Offre!$C$8^Param!$B$3)*1_Friction!I10 -> 24.424095 | J10: =Offre!$E$9*(Offre!$C$9^Param!$B$3)*1_Friction!J10 -> 19.380428 | K10: =Offre!$E$10*(Offre!$C$10^Param!$B$3)*1_Friction!K10 -> 12.076434 | L10: =Offre!$E$11*(Offre!$C$11^Param!$B$3)*1_Friction!L10 -> 12.215733 | M10: =Offre!$E$12*(Offre!$C$12^Param!$B$3)*1_Friction!M10 -> 66.194586 | N10: =Offre!$E$13*(Offre!$C$13^Param!$B$3)*1_Friction!N10 -> 8.9446569 | O10: =Offre!$E$14*(Offre!$C$14^Param!$B$3)*1_Friction!O10 -> 28.338208 | P10: =Offre!$E$15*(Offre!$C$15^Param!$B$3)*1_Friction!P10 -> 13.742863 | Q10: =Offre!$E$16*(Offre!$C$16^Param!$B$3)*1_Friction!Q10 -> 120.62951 | R10: =Offre!$E$17*(Offre!$C$17^Param!$B$3)*1_Friction!R10 -> 16.050363 | S10: =Offre!$E$18*(Offre!$C$18^Param!$B$3)*1_Friction!S10 -> 11.982938 | T10: =Offre!$E$19*(Offre!$C$19^Param!$B$3)*1_Friction!T10 -> 8.5354121 | U10: =Offre!$E$20*(Offre!$C$20^Param!$B$3)*1_Friction!U10 -> 3.0866574 | V10: =Offre!$E$21*(Offre!$C$21^Param!$B$3)*1_Friction!V10 -> 9.6223566 | W10: =Offre!$E$22*(Offre!$C$22^Param!$B$3)*1_Friction!W10 -> 1.5950722 | X10: =Offre!$E$23*(Offre!$C$23^Param!$B$3)*1_Friction!X10 -> 2.1570506 | Y10: =Offre!$E$24*(Offre!$C$24^Param!$B$3)*1_Friction!Y10 -> 1.4358547 | Z10: =Offre!$E$25*(Offre!$C$25^Param!$B$3)*1_Friction!Z10 -> 3.5113901 | AA10: =Offre!$E$26*(Offre!$C$26^Param!$B$3)*1_Friction!AA10 -> 6.2810023 | AB10: =Offre!$E$27*(Offre!$C$27^Param!$B$3)*1_Friction!AB10 -> 2.6695699 | AC10: =Offre!$E$28*(Offre!$C$28^Param!$B$3)*1_Friction!AC10 -> 0 | AD10: =Offre!$E$29*(Offre!$C$29^Param!$B$3)*1_Friction!AD10 -> 0 | AE10: =Offre!$E$30*(Offre!$C$30^Param!$B$3)*1_Friction!AE10 -> 0 | AF10: =Offre!$E$31*(Offre!$C$31^Param!$B$3)*1_Friction!AF10 -> 0 | AG10: =Offre!$E$32*(Offre!$C$32^Param!$B$3)*1_Friction!AG10 -> 0 | AH10: =Offre!$E$33*(Offre!$C$33^Param!$B$3)*1_Friction!AH10 -> 38.981795 | AI10: =Offre!$E$34*(Offre!$C$34^Param!$B$3)*1_Friction!AI10 -> 3.7880647 | AJ10: =Offre!$E$35*(Offre!$C$35^Param!$B$3)*1_Friction!AJ10 -> 3.0698495 | AK10: =Offre!$E$36*(Offre!$C$36^Param!$B$3)*1_Friction!AK10 -> 0 | AL10: =Offre!$E$37*(Offre!$C$37^Param!$B$3)*1_Friction!AL10 -> 0 | AM10: =Offre!$E$38*(Offre!$C$38^Param!$B$3)*1_Friction!AM10 -> 14.627884 | AN10: =Offre!$E$39*(Offre!$C$39^Param!$B$3)*1_Friction!AN10 -> 0 | AO10: =SUM(C10:AN10) -> 610.52668
A11: 05.091.03.11. | B11: Commune de Foum El Anceur | C11: =Offre!$E$2*(Offre!$C$2^Param!$B$3)*1_Friction!C11 -> 1.5078651 | D11: =Offre!$E$3*(Offre!$C$3^Param!$B$3)*1_Friction!D11 -> 5.946241 | E11: =Offre!$E$4*(Offre!$C$4^Param!$B$3)*1_Friction!E11 -> 66.003275 | F11: =Offre!$E$5*(Offre!$C$5^Param!$B$3)*1_Friction!F11 -> 12.256287 | G11: =Offre!$E$6*(Offre!$C$6^Param!$B$3)*1_Friction!G11 -> 36.97389 | H11: =Offre!$E$7*(Offre!$C$7^Param!$B$3)*1_Friction!H11 -> 7.9665866 | I11: =Offre!$E$8*(Offre!$C$8^Param!$B$3)*1_Friction!I11 -> 19.986948 | J11: =Offre!$E$9*(Offre!$C$9^Param!$B$3)*1_Friction!J11 -> 15.567954 | K11: =Offre!$E$10*(Offre!$C$10^Param!$B$3)*1_Friction!K11 -> 9.729971 | L11: =Offre!$E$11*(Offre!$C$11^Param!$B$3)*1_Friction!L11 -> 10.252448 | M11: =Offre!$E$12*(Offre!$C$12^Param!$B$3)*1_Friction!M11 -> 47.569928 | N11: =Offre!$E$13*(Offre!$C$13^Param!$B$3)*1_Friction!N11 -> 7.1353121 | O11: =Offre!$E$14*(Offre!$C$14^Param!$B$3)*1_Friction!O11 -> 23.318106 | P11: =Offre!$E$15*(Offre!$C$15^Param!$B$3)*1_Friction!P11 -> 11.619442 | Q11: =Offre!$E$16*(Offre!$C$16^Param!$B$3)*1_Friction!Q11 -> 105.06181 | R11: =Offre!$E$17*(Offre!$C$17^Param!$B$3)*1_Friction!R11 -> 13.669931 | S11: =Offre!$E$18*(Offre!$C$18^Param!$B$3)*1_Friction!S11 -> 10.252448 | T11: =Offre!$E$19*(Offre!$C$19^Param!$B$3)*1_Friction!T11 -> 1.2100601 | U11: =Offre!$E$20*(Offre!$C$20^Param!$B$3)*1_Friction!U11 -> 0.5613269 | V11: =Offre!$E$21*(Offre!$C$21^Param!$B$3)*1_Friction!V11 -> 0 | W11: =Offre!$E$22*(Offre!$C$22^Param!$B$3)*1_Friction!W11 -> 0 | X11: =Offre!$E$23*(Offre!$C$23^Param!$B$3)*1_Friction!X11 -> 0 | Y11: =Offre!$E$24*(Offre!$C$24^Param!$B$3)*1_Friction!Y11 -> 0 | Z11: =Offre!$E$25*(Offre!$C$25^Param!$B$3)*1_Friction!Z11 -> 0 | AA11: =Offre!$E$26*(Offre!$C$26^Param!$B$3)*1_Friction!AA11 -> 0 | AB11: =Offre!$E$27*(Offre!$C$27^Param!$B$3)*1_Friction!AB11 -> 0 | AC11: =Offre!$E$28*(Offre!$C$28^Param!$B$3)*1_Friction!AC11 -> 0 | AD11: =Offre!$E$29*(Offre!$C$29^Param!$B$3)*1_Friction!AD11 -> 0 | AE11: =Offre!$E$30*(Offre!$C$30^Param!$B$3)*1_Friction!AE11 -> 0 | AF11: =Offre!$E$31*(Offre!$C$31^Param!$B$3)*1_Friction!AF11 -> 0 | AG11: =Offre!$E$32*(Offre!$C$32^Param!$B$3)*1_Friction!AG11 -> 0 | AH11: =Offre!$E$33*(Offre!$C$33^Param!$B$3)*1_Friction!AH11 -> 34.631486 | AI11: =Offre!$E$34*(Offre!$C$34^Param!$B$3)*1_Friction!AI11 -> 0.55461087 | AJ11: =Offre!$E$35*(Offre!$C$35^Param!$B$3)*1_Friction!AJ11 -> 0 | AK11: =Offre!$E$36*(Offre!$C$36^Param!$B$3)*1_Friction!AK11 -> 0 | AL11: =Offre!$E$37*(Offre!$C$37^Param!$B$3)*1_Friction!AL11 -> 0 | AM11: =Offre!$E$38*(Offre!$C$38^Param!$B$3)*1_Friction!AM11 -> 4.0473121 | AN11: =Offre!$E$39*(Offre!$C$39^Param!$B$3)*1_Friction!AN11 -> 0 | AO11: =SUM(C11:AN11) -> 445.82324
